Workbook

Sheet README
A1: Docker RAM & Latency Benchmark Suite -- Results Workbook
A3: Model: Network-layer CNN-LSTM | 37 features (measured, 100k-row stratified subsample) | 8 classes | 79,688 total parameters
A4: Partitioning: 2 clients, Dirichlet(alpha=0.7, seed=42), client0=31,332 train/7,834 test rows, client1=26,566 train/6,642 test rows
A5: Training: 3 simulated FL rounds, 2 local epochs/round, batch_size=256 (512 for DP-SGD)
A6: Resource profiles: both capped at 2048MB RAM (headroom, not a tight constraint) -- only vCPU allocation differs: 1.0 vCPU ("unthrottled") vs 0.5 vCPU ("throttled")
A7: Encryption (HE modes): CKKS via TenSEAL, poly_modulus_degree=4096, depth-1 coefficient chain -- 64-bit security (Docker-tuned config)
A8: DP-SGD: Opacus PrivacyEngine, target eps=3.0, delta=1e-5, max_grad_norm=1.0, DP batch_size=512
A9: Krum/ZKP-threshold timing: measured at n=10 synthetic clients (2 real + 8 jittered copies of real trained params) to match the main pipeline's NUM_CLIENTS=10 -- TIMING ONLY, not an accuracy or detection-rate result.
A11: SHEETS IN THIS WORKBOOK
A12: Summary -- one row per run (mode x CPU profile), key averages, formula-driven from the raw sheets below
A13: Raw_Training -- every per-client, per-round training/encryption/DP/ZKP/communication measurement (client-side)
A14: Raw_Communication -- every per-submission measurement from the receiving daemon (server-side view of the same events)
... A17: Known_Issues -- two data-quality notes that affect how specific columns should be read; read before citing anything from this workbook

Sheet Summary
A1: Mode | B1: Mode (label) | C1: CPU Profile | D1: vCPU | E1: Total Params | F1: Num Features | G1: Client0 Train Rows | H1: Client1 Train Rows | I1: Avg Train Time/Round - C0 (s) | J1: Avg Train Time/Round - C1 (s) | K1: Avg DP Setup Time (s) | L1: Avg HE Encrypt Time (s) | M1: Avg ZKP Proof Time (s) | N1: Avg Serialize Time (s) | O1: Avg Comm. Send Time - Client (s) | P1: Avg Payload Bytes (Client) | Q1: Avg Daemon Recv Time (s) | R1: Client0 Peak RAM (MB) | S1: Client1 Peak RAM (MB) | T1: Server Peak RAM (MB) | U1: Avg Aggregate Time (s) | V1: Avg Decrypt Time (s) | W1: Avg ZKP Verify Time (s) | X1: Avg ZKP MAD Threshold Time (s) | Y1: Avg Adaptive Krum Time (s) | Z1: Avg Round Wall Time - C0 (s) | AA1: Avg Round Wall Time - C1 (s)
A2: baseline | B2: Baseline (no defense) | C2: unthrottled | D2: 1 | E2: 79688 | F2: 37 | G2: 31332 | H2: 26566 | I2: =IFERROR(AVERAGEIFS(Raw_Training!$J$2:$J$61,Raw_Training!$A$2:$A$61,$A2,Raw_Training!$C$2:$C$61,$C2,Raw_Training!$E$2:$E$61,0),"") -> 134.63013 | J2: =IFERROR(AVERAGEIFS(Raw_Training!$J$2:$J$61,Raw_Training!$A$2:$A$61,$A2,Raw_Training!$C$2:$C$61,$C2,Raw_Training!$E$2:$E$61,1),"") -> 102.8673 | K2: =IFERROR(AVERAGEIFS(Raw_Training!$I$2:$I$61,Raw_Training!$A$2:$A$61,$A2,Raw_Training!$C$2:$C$61,$C2),"") | L2: =IFERROR(AVERAGEIFS(Raw_Training!$K$2:$K$61,Raw_Training!$A$2:$A$61,$A2,Raw_Training!$C$2:$C$61,$C2),"") | M2: =IFERROR(AVERAGEIFS(Raw_Training!$L$2:$L$61,Raw_Training!$A$2:$A$61,$A2,Raw_Training!$C$2:$C$61,$C2),"") | N2: =IFERROR(AVERAGEIFS(Raw_Training!$S$2:$S$61,Raw_Training!$A$2:$A$61,$A2,Raw_Training!$C$2:$C$61,$C2),"") -> 0.12271333 | O2: =IFERROR(AVERAGEIFS(Raw_Training!$T$2:$T$61,Raw_Training!$A$2:$A$61,$A2,Raw_Training!$C$2:$C$61,$C2),"") -> 0.084155 | P2: =IFERROR(AVERAGEIFS(Raw_Training!$U$2:$U$61,Raw_Training!$A$2:$A$61,$A2,Raw_Training!$C$2:$C$61,$C2),"") -> 1755723.5 | Q2: =IFERROR(AVERAGEIFS(Raw_Communication!$F$2:$F$61,Raw_Communication!$A$2:$A$61,$A2,Raw_Communication!$C$2:$C$61,$C2),"") -> 0.07103 | R2: =IFERROR(AVERAGEIFS(Raw_RAM!$E$2:$E$31,Raw_RAM!$A$2:$A$31,$A2,Raw_RAM!$C$2:$C$31,$C2,Raw_RAM!$D$2:$D$31,"Client 0"),"") -> 382.9 | S2: =IFERROR(AVERAGEIFS(Raw_RAM!$E$2:$E$31,Raw_RAM!$A$2:$A$31,$A2,Raw_RAM!$C$2:$C$31,$C2,Raw_RAM!$D$2:$D$31,"Client 1"),"") -> 382.4 | T2: =IFERROR(AVERAGEIFS(Raw_RAM!$E$2:$E$31,Raw_RAM!$A$2:$A$31,$A2,Raw_RAM!$C$2:$C$31,$C2,Raw_RAM!$D$2:$D$31,"Server (aggregation)"),"") -> 63.3 | U2: =IFERROR(AVERAGEIFS(Raw_Aggregation!$E$2:$E$31,Raw_Aggregation!$A$2:$A$31,$A2,Raw_Aggregation!$C$2:$C$31,$C2),"") | V2: =IFERROR(AVERAGEIFS(Raw_Aggregation!$F$2:$F$31,Raw_Aggregation!$A$2:$A$31,$A2,Raw_Aggregation!$C$2:$C$31,$C2),"") | W2: =IFERROR(AVERAGEIFS(Raw_Aggregation!$G$2:$G$31,Raw_Aggregation!$A$2:$A$31,$A2,Raw_Aggregation!$C$2:$C$31,$C2),"") | X2: =IFERROR(AVERAGEIFS(Raw_Aggregation!$H$2:$H$31,Raw_Aggregation!$A$2:$A$31,$A2,Raw_Aggregation!$C$2:$C$31,$C2),"") | Y2: =IFERROR(AVERAGEIFS(Raw_Aggregation!$I$2:$I$31,Raw_Aggregation!$A$2:$A$31,$A2,Raw_Aggregation!$C$2:$C$31,$C2),"") -> 0.023536667 | Z2: =IFERROR(AVERAGEIFS(Raw_Training!$W$2:$W$61,Raw_Training!$A$2:$A$61,$A2,Raw_Training!$C$2:$C$61,$C2,Raw_Training!$E$2:$E$61,0),"") -> 135.79983 | AA2: =IFERROR(AVERAGEIFS(Raw_Training!$W$2:$W$61,Raw_Training!$A$2:$A$61,$A2,Raw_Training!$C$2:$C$61,$C2,Raw_Training!$E$2:$E$61,1),"") -> 104.24467
A3: baseline | B3: Baseline (no defense) | C3: throttled | D3: 0.5 | E3: 79688 | F3: 37 | G3: 31332 | H3: 26566 | I3: =IFERROR(AVERAGEIFS(Raw_Training!$J$2:$J$61,Raw_Training!$A$2:$A$61,$A3,Raw_Training!$C$2:$C$61,$C3,Raw_Training!$E$2:$E$61,0),"") -> 432.92867 | J3: =IFERROR(AVERAGEIFS(Raw_Training!$J$2:$J$61,Raw_Training!$A$2:$A$61,$A3,Raw_Training!$C$2:$C$61,$C3,Raw_Training!$E$2:$E$61,1),"") -> 497.61437 | K3: =IFERROR(AVERAGEIFS(Raw_Training!$I$2:$I$61,Raw_Training!$A$2:$A$61,$A3,Raw_Training!$C$2:$C$61,$C3),"") | L3: =IFERROR(AVERAGEIFS(Raw_Training!$K$2:$K$61,Raw_Training!$A$2:$A$61,$A3,Raw_Training!$C$2:$C$61,$C3),"") | M3: =IFERROR(AVERAGEIFS(Raw_Training!$L$2:$L$61,Raw_Training!$A$2:$A$61,$A3,Raw_Training!$C$2:$C$61,$C3),"") | N3: =IFERROR(AVERAGEIFS(Raw_Training!$S$2:$S$61,Raw_Training!$A$2:$A$61,$A3,Raw_Training!$C$2:$C$61,$C3),"") -> 0.21766667 | O3: =IFERROR(AVERAGEIFS(Raw_Training!$T$2:$T$61,Raw_Training!$A$2:$A$61,$A3,Raw_Training!$C$2:$C$61,$C3),"") -> 0.17406167 | P3: =IFERROR(AVERAGEIFS(Raw_Training!$U$2:$U$61,Raw_Training!$A$2:$A$61,$A3,Raw_Training!$C$2:$C$61,$C3),"") -> 1755777 | Q3: =IFERROR(AVERAGEIFS(Raw_Communication!$F$2:$F$61,Raw_Communication!$A$2:$A$61,$A3,Raw_Communication!$C$2:$C$61,$C3),"") -> 0.1541 | R3: =IFERROR(AVERAGEIFS(Raw_RAM!$E$2:$E$31,Raw_RAM!$A$2:$A$31,$A3,Raw_RAM!$C$2:$C$31,$C3,Raw_RAM!$D$2:$D$31,"Client 0"),"") -> 385.9 | S3: =IFERROR(AVERAGEIFS(Raw_RAM!$E$2:$E$31,Raw_RAM!$A$2:$A$31,$A3,Raw_RAM!$C$2:$C$31,$C3,Raw_RAM!$D$2:$D$31,"Client 1"),"") -> 382.4 | T3: =IFERROR(AVERAGEIFS(Raw_RAM!$E$2:$E$31,Raw_RAM!$A$2:$A$31,$A3,Raw_RAM!$C$2:$C$31,$C3,Raw_RAM!$D$2:$D$31,"Server (aggregation)"),"") -> 63.1 | U3: =IFERROR(AVERAGEIFS(Raw_Aggregation!$E$2:$E$31,Raw_Aggregation!$A$2:$A$31,$A3,Raw_Aggregation!$C$2:$C$31,$C3),"") | V3: =IFERROR(AVERAGEIFS(Raw_Aggregation!$F$2:$F$31,Raw_Aggregation!$A$2:$A$31,$A3,Raw_Aggregation!$C$2:$C$31,$C3),"") | W3: =IFERROR(AVERAGEIFS(Raw_Aggregation!$G$2:$G$31,Raw_Aggregation!$A$2:$A$31,$A3,Raw_Aggregation!$C$2:$C$31,$C3),"") | X3: =IFERROR(AVERAGEIFS(Raw_Aggregation!$H$2:$H$31,Raw_Aggregation!$A$2:$A$31,$A3,Raw_Aggregation!$C$2:$C$31,$C3),"") | Y3: =IFERROR(AVERAGEIFS(Raw_Aggregation!$I$2:$I$31,Raw_Aggregation!$A$2:$A$31,$A3,Raw_Aggregation!$C$2:$C$31,$C3),"") -> 0.061776667 | Z3: =IFERROR(AVERAGEIFS(Raw_Training!$W$2:$W$61,Raw_Training!$A$2:$A$61,$A3,Raw_Training!$C$2:$C$61,$C3,Raw_Training!$E$2:$E$61,0),"") -> 434.49707 | AA3: =IFERROR(AVERAGEIFS(Raw_Training!$W$2:$W$61,Raw_Training!$A$2:$A$61,$A3,Raw_Training!$C$2:$C$61,$C3,Raw_Training!$E$2:$E$61,1),"") -> 499.2431
A4: he_full | B4: Full-Model HE (CKKS) | C4: unthrottled | D4: 1 | E4: 79688 | F4: 37 | G4: 31332 | H4: 26566 | I4: =IFERROR(AVERAGEIFS(Raw_Training!$J$2:$J$61,Raw_Training!$A$2:$A$61,$A4,Raw_Training!$C$2:$C$61,$C4,Raw_Training!$E$2:$E$61,0),"") -> 134.967 | J4: =IFERROR(AVERAGEIFS(Raw_Training!$J$2:$J$61,Raw_Training!$A$2:$A$61,$A4,Raw_Training!$C$2:$C$61,$C4,Raw_Training!$E$2:$E$61,1),"") -> 82.2456 | K4: =IFERROR(AVERAGEIFS(Raw_Training!$I$2:$I$61,Raw_Training!$A$2:$A$61,$A4,Raw_Training!$C$2:$C$61,$C4),"") | L4: =IFERROR(AVERAGEIFS(Raw_Training!$K$2:$K$61,Raw_Training!$A$2:$A$61,$A4,Raw_Training!$C$2:$C$61,$C4),"") -> 0.33611667 | M4: =IFERROR(AVERAGEIFS(Raw_Training!$L$2:$L$61,Raw_Training!$A$2:$A$61,$A4,Raw_Training!$C$2:$C$61,$C4),"") | N4: =IFERROR(AVERAGEIFS(Raw_Training!$S$2:$S$61,Raw_Training!$A$2:$A$61,$A4,Raw_Training!$C$2:$C$61,$C4),"") -> 0.03137 | O4: =IFERROR(AVERAGEIFS(Raw_Training!$T$2:$T$61,Raw_Training!$A$2:$A$61,$A4,Raw_Training!$C$2:$C$61,$C4),"") -> 0.04394 | P4: =IFERROR(AVERAGEIFS(Raw_Training!$U$2:$U$61,Raw_Training!$A$2:$A$61,$A4,Raw_Training!$C$2:$C$61,$C4),"") -> 4562887.3 | Q4: =IFERROR(AVERAGEIFS(Raw_Communication!$F$2:$F$61,Raw_Communication!$A$2:$A$61,$A4,Raw_Communication!$C$2:$C$61,$C4),"") -> 0.032978333 | R4: =IFERROR(AVERAGEIFS(Raw_RAM!$E$2:$E$31,Raw_RAM!$A$2:$A$31,$A4,Raw_RAM!$C$2:$C$31,$C4,Raw_RAM!$D$2:$D$31,"Client 0"),"") -> 401.1 | S4: =IFERROR(AVERAGEIFS(Raw_RAM!$E$2:$E$31,Raw_RAM!$A$2:$A$31,$A4,Raw_RAM!$C$2:$C$31,$C4,Raw_RAM!$D$2:$D$31,"Client 1"),"") -> 396.2 | T4: =IFERROR(AVERAGEIFS(Raw_RAM!$E$2:$E$31,Raw_RAM!$A$2:$A$31,$A4,Raw_RAM!$C$2:$C$31,$C4,Raw_RAM!$D$2:$D$31,"Server (aggregation)"),"") -> 72.9 | U4: =IFERROR(AVERAGEIFS(Raw_Aggregation!$E$2:$E$31,Raw_Aggregation!$A$2:$A$31,$A4,Raw_Aggregation!$C$2:$C$31,$C4),"") -> 0.11674667 | V4: =IFERROR(AVERAGEIFS(Raw_Aggregation!$F$2:$F$31,Raw_Aggregation!$A$2:$A$31,$A4,Raw_Aggregation!$C$2:$C$31,$C4),"") -> 0.02738 | W4: =IFERROR(AVERAGEIFS(Raw_Aggregation!$G$2:$G$31,Raw_Aggregation!$A$2:$A$31,$A4,Raw_Aggregation!$C$2:$C$31,$C4),"") | X4: =IFERROR(AVERAGEIFS(Raw_Aggregation!$H$2:$H$31,Raw_Aggregation!$A$2:$A$31,$A4,Raw_Aggregation!$C$2:$C$31,$C4),"") | Y4: =IFERROR(AVERAGEIFS(Raw_Aggregation!$I$2:$I$31,Raw_Aggregation!$A$2:$A$31,$A4,Raw_Aggregation!$C$2:$C$31,$C4),"") | Z4: =IFERROR(AVERAGEIFS(Raw_Training!$W$2:$W$61,Raw_Training!$A$2:$A$61,$A4,Raw_Training!$C$2:$C$61,$C4,Raw_Training!$E$2:$E$61,0),"") -> 135.6872 | AA4: =IFERROR(AVERAGEIFS(Raw_Training!$W$2:$W$61,Raw_Training!$A$2:$A$61,$A4,Raw_Training!$C$2:$C$61,$C4,Raw_Training!$E$2:$E$61,1),"") -> 82.9662
A5: he_full | B5: Full-Model HE (CKKS) | C5: throttled | D5: 0.5 | E5: 79688 | F5: 37 | G5: 31332 | H5: 26566 | I5: =IFERROR(AVERAGEIFS(Raw_Training!$J$2:$J$61,Raw_Training!$A$2:$A$61,$A5,Raw_Training!$C$2:$C$61,$C5,Raw_Training!$E$2:$E$61,0),"") -> 630.33323 | J5: =IFERROR(AVERAGEIFS(Raw_Training!$J$2:$J$61,Raw_Training!$A$2:$A$61,$A5,Raw_Training!$C$2:$C$61,$C5,Raw_Training!$E$2:$E$61,1),"") -> 193.8183 | K5: =IFERROR(AVERAGEIFS(Raw_Training!$I$2:$I$61,Raw_Training!$A$2:$A$61,$A5,Raw_Training!$C$2:$C$61,$C5),"") | L5: =IFERROR(AVERAGEIFS(Raw_Training!$K$2:$K$61,Raw_Training!$A$2:$A$61,$A5,Raw_Training!$C$2:$C$61,$C5),"") -> 0.59403333 | M5: =IFERROR(AVERAGEIFS(Raw_Training!$L$2:$L$61,Raw_Training!$A$2:$A$61,$A5,Raw_Training!$C$2:$C$61,$C5),"") | N5: =IFERROR(AVERAGEIFS(Raw_Training!$S$2:$S$61,Raw_Training!$A$2:$A$61,$A5,Raw_Training!$C$2:$C$61,$C5),"") -> 0.0339 | O5: =IFERROR(AVERAGEIFS(Raw_Training!$T$2:$T$61,Raw_Training!$A$2:$A$61,$A5,Raw_Training!$C$2:$C$61,$C5),"") -> 0.08223 | P5: =IFERROR(AVERAGEIFS(Raw_Training!$U$2:$U$61,Raw_Training!$A$2:$A$61,$A5,Raw_Training!$C$2:$C$61,$C5),"") -> 4563279.3 | Q5: =IFERROR(AVERAGEIFS(Raw_Communication!$F$2:$F$61,Raw_Communication!$A$2:$A$61,$A5,Raw_Communication!$C$2:$C$61,$C5),"") -> 0.055476667 | R5: =IFERROR(AVERAGEIFS(Raw_RAM!$E$2:$E$31,Raw_RAM!$A$2:$A$31,$A5,Raw_RAM!$C$2:$C$31,$C5,Raw_RAM!$D$2:$D$31,"Client 0"),"") -> 399.5 | S5: =IFERROR(AVERAGEIFS(Raw_RAM!$E$2:$E$31,Raw_RAM!$A$2:$A$31,$A5,Raw_RAM!$C$2:$C$31,$C5,Raw_RAM!$D$2:$D$31,"Client 1"),"") -> 399.5 | T5: =IFERROR(AVERAGEIFS(Raw_RAM!$E$2:$E$31,Raw_RAM!$A$2:$A$31,$A5,Raw_RAM!$C$2:$C$31,$C5,Raw_RAM!$D$2:$D$31,"Server (aggregation)"),"") -> 72.9 | U5: =IFERROR(AVERAGEIFS(Raw_Aggregation!$E$2:$E$31,Raw_Aggregation!$A$2:$A$31,$A5,Raw_Aggregation!$C$2:$C$31,$C5),"") -> 0.25566667 | V5: =IFERROR(AVERAGEIFS(Raw_Aggregation!$F$2:$F$31,Raw_Aggregation!$A$2:$A$31,$A5,Raw_Aggregation!$C$2:$C$31,$C5),"") -> 0.044823333 | W5: =IFERROR(AVERAGEIFS(Raw_Aggregation!$G$2:$G$31,Raw_Aggregation!$A$2:$A$31,$A5,Raw_Aggregation!$C$2:$C$31,$C5),"") | X5: =IFERROR(AVERAGEIFS(Raw_Aggregation!$H$2:$H$31,Raw_Aggregation!$A$2:$A$31,$A5,Raw_Aggregation!$C$2:$C$31,$C5),"") | Y5: =IFERROR(AVERAGEIFS(Raw_Aggregation!$I$2:$I$31,Raw_Aggregation!$A$2:$A$31,$A5,Raw_Aggregation!$C$2:$C$31,$C5),"") | Z5: =IFERROR(AVERAGEIFS(Raw_Training!$W$2:$W$61,Raw_Training!$A$2:$A$61,$A5,Raw_Training!$C$2:$C$61,$C5,Raw_Training!$E$2:$E$61,0),"") -> 631.6327 | AA5: =IFERROR(AVERAGEIFS(Raw_Training!$W$2:$W$61,Raw_Training!$A$2:$A$61,$A5,Raw_Training!$C$2:$C$61,$C5,Raw_Training!$E$2:$E$61,1),"") -> 195.06133
A6: he_partial | B6: Partial HE (classifier head only) | C6: unthrottled | D6: 1 | E6: 79688 | F6: 37 | G6: 31332 | H6: 26566 | I6: =IFERROR(AVERAGEIFS(Raw_Training!$J$2:$J$61,Raw_Training!$A$2:$A$61,$A6,Raw_Training!$C$2:$C$61,$C6,Raw_Training!$E$2:$E$61,0),"") -> 140.86973 | J6: =IFERROR(AVERAGEIFS(Raw_Training!$J$2:$J$61,Raw_Training!$A$2:$A$61,$A6,Raw_Training!$C$2:$C$61,$C6,Raw_Training!$E$2:$E$61,1),"") -> 109.5597 | K6: =IFERROR(AVERAGEIFS(Raw_Training!$I$2:$I$61,Raw_Training!$A$2:$A$61,$A6,Raw_Training!$C$2:$C$61,$C6),"") | L6: =IFERROR(AVERAGEIFS(Raw_Training!$K$2:$K$61,Raw_Training!$A$2:$A$61,$A6,Raw_Training!$C$2:$C$61,$C6),"") -> 0.03655 | M6: =IFERROR(AVERAGEIFS(Raw_Training!$L$2:$L$61,Raw_Training!$A$2:$A$61,$A6,Raw_Training!$C$2:$C$61,$C6),"") | N6: =IFERROR(AVERAGEIFS(Raw_Training!$S$2:$S$61,Raw_Training!$A$2:$A$61,$A6,Raw_Training!$C$2:$C$61,$C6),"") -> 0.12258833 | O6: =IFERROR(AVERAGEIFS(Raw_Training!$T$2:$T$61,Raw_Training!$A$2:$A$61,$A6,Raw_Training!$C$2:$C$61,$C6),"") -> 0.083893333 | P6: =IFERROR(AVERAGEIFS(Raw_Training!$U$2:$U$61,Raw_Training!$A$2:$A$61,$A6,Raw_Training!$C$2:$C$61,$C6),"") -> 1997507 | Q6: =IFERROR(AVERAGEIFS(Raw_Communication!$F$2:$F$61,Raw_Communication!$A$2:$A$61,$A6,Raw_Communication!$C$2:$C$61,$C6),"") -> 0.07366 | R6: =IFERROR(AVERAGEIFS(Raw_RAM!$E$2:$E$31,Raw_RAM!$A$2:$A$31,$A6,Raw_RAM!$C$2:$C$31,$C6,Raw_RAM!$D$2:$D$31,"Client 0"),"") -> 394.7 | S6: =IFERROR(AVERAGEIFS(Raw_RAM!$E$2:$E$31,Raw_RAM!$A$2:$A$31,$A6,Raw_RAM!$C$2:$C$31,$C6,Raw_RAM!$D$2:$D$31,"Client 1"),"") -> 392.8 | T6: =IFERROR(AVERAGEIFS(Raw_RAM!$E$2:$E$31,Raw_RAM!$A$2:$A$31,$A6,Raw_RAM!$C$2:$C$31,$C6,Raw_RAM!$D$2:$D$31,"Server (aggregation)"),"") -> 51.5 | U6: =IFERROR(AVERAGEIFS(Raw_Aggregation!$E$2:$E$31,Raw_Aggregation!$A$2:$A$31,$A6,Raw_Aggregation!$C$2:$C$31,$C6),"") -> 0.01256 | V6: =IFERROR(AVERAGEIFS(Raw_Aggregation!$F$2:$F$31,Raw_Aggregation!$A$2:$A$31,$A6,Raw_Aggregation!$C$2:$C$31,$C6),"") -> 0.0017033333 | W6: =IFERROR(AVERAGEIFS(Raw_Aggregation!$G$2:$G$31,Raw_Aggregation!$A$2:$A$31,$A6,Raw_Aggregation!$C$2:$C$31,$C6),"") | X6: =IFERROR(AVERAGEIFS(Raw_Aggregation!$H$2:$H$31,Raw_Aggregation!$A$2:$A$31,$A6,Raw_Aggregation!$C$2:$C$31,$C6),"") | Y6: =IFERROR(AVERAGEIFS(Raw_Aggregation!$I$2:$I$31,Raw_Aggregation!$A$2:$A$31,$A6,Raw_Aggregation!$C$2:$C$31,$C6),"") | Z6: =IFERROR(AVERAGEIFS(Raw_Training!$W$2:$W$61,Raw_Training!$A$2:$A$61,$A6,Raw_Training!$C$2:$C$61,$C6,Raw_Training!$E$2:$E$61,0),"") -> 142.12723 | AA6: =IFERROR(AVERAGEIFS(Raw_Training!$W$2:$W$61,Raw_Training!$A$2:$A$61,$A6,Raw_Training!$C$2:$C$61,$C6,Raw_Training!$E$2:$E$61,1),"") -> 110.83877
A7: he_partial | B7: Partial HE (classifier head only) | C7: throttled | D7: 0.5 | E7: 79688 | F7: 37 | G7: 31332 | H7: 26566 | I7: =IFERROR(AVERAGEIFS(Raw_Training!$J$2:$J$61,Raw_Training!$A$2:$A$61,$A7,Raw_Training!$C$2:$C$61,$C7,Raw_Training!$E$2:$E$61,0),"") -> 604.72747 | J7: =IFERROR(AVERAGEIFS(Raw_Training!$J$2:$J$61,Raw_Training!$A$2:$A$61,$A7,Raw_Training!$C$2:$C$61,$C7,Raw_Training!$E$2:$E$61,1),"") -> 353.38087 | K7: =IFERROR(AVERAGEIFS(Raw_Training!$I$2:$I$61,Raw_Training!$A$2:$A$61,$A7,Raw_Training!$C$2:$C$61,$C7),"") | L7: =IFERROR(AVERAGEIFS(Raw_Training!$K$2:$K$61,Raw_Training!$A$2:$A$61,$A7,Raw_Training!$C$2:$C$61,$C7),"") -> 0.066583333 | M7: =IFERROR(AVERAGEIFS(Raw_Training!$L$2:$L$61,Raw_Training!$A$2:$A$61,$A7,Raw_Training!$C$2:$C$61,$C7),"") | N7: =IFERROR(AVERAGEIFS(Raw_Training!$S$2:$S$61,Raw_Training!$A$2:$A$61,$A7,Raw_Training!$C$2:$C$61,$C7),"") -> 0.20706833 | O7: =IFERROR(AVERAGEIFS(Raw_Training!$T$2:$T$61,Raw_Training!$A$2:$A$61,$A7,Raw_Training!$C$2:$C$61,$C7),"") -> 0.132985 | P7: =IFERROR(AVERAGEIFS(Raw_Training!$U$2:$U$61,Raw_Training!$A$2:$A$61,$A7,Raw_Training!$C$2:$C$61,$C7),"") -> 1997686.8 | Q7: =IFERROR(AVERAGEIFS(Raw_Communication!$F$2:$F$61,Raw_Communication!$A$2:$A$61,$A7,Raw_Communication!$C$2:$C$61,$C7),"") -> 0.12113 | R7: =IFERROR(AVERAGEIFS(Raw_RAM!$E$2:$E$31,Raw_RAM!$A$2:$A$31,$A7,Raw_RAM!$C$2:$C$31,$C7,Raw_RAM!$D$2:$D$31,"Client 0"),"") -> 395.2 | S7: =IFERROR(AVERAGEIFS(Raw_RAM!$E$2:$E$31,Raw_RAM!$A$2:$A$31,$A7,Raw_RAM!$C$2:$C$31,$C7,Raw_RAM!$D$2:$D$31,"Client 1"),"") -> 392.6 | T7: =IFERROR(AVERAGEIFS(Raw_RAM!$E$2:$E$31,Raw_RAM!$A$2:$A$31,$A7,Raw_RAM!$C$2:$C$31,$C7,Raw_RAM!$D$2:$D$31,"Server (aggregation)"),"") -> 53.9 | U7: =IFERROR(AVERAGEIFS(Raw_Aggregation!$E$2:$E$31,Raw_Aggregation!$A$2:$A$31,$A7,Raw_Aggregation!$C$2:$C$31,$C7),"") -> 0.033983333 | V7: =IFERROR(AVERAGEIFS(Raw_Aggregation!$F$2:$F$31,Raw_Aggregation!$A$2:$A$31,$A7,Raw_Aggregation!$C$2:$C$31,$C7),"") -> 0.002 | W7: =IFERROR(AVERAGEIFS(Raw_Aggregation!$G$2:$G$31,Raw_Aggregation!$A$2:$A$31,$A7,Raw_Aggregation!$C$2:$C$31,$C7),"") | X7: =IFERROR(AVERAGEIFS(Raw_Aggregation!$H$2:$H$31,Raw_Aggregation!$A$2:$A$31,$A7,Raw_Aggregation!$C$2:$C$31,$C7),"") | Y7: =IFERROR(AVERAGEIFS(Raw_Aggregation!$I$2:$I$31,Raw_Aggregation!$A$2:$A$31,$A7,Raw_Aggregation!$C$2:$C$31,$C7),"") | Z7: =IFERROR(AVERAGEIFS(Raw_Training!$W$2:$W$61,Raw_Training!$A$2:$A$61,$A7,Raw_Training!$C$2:$C$61,$C7,Raw_Training!$E$2:$E$61,0),"") -> 606.32637 | AA7: =IFERROR(AVERAGEIFS(Raw_Training!$W$2:$W$61,Raw_Training!$A$2:$A$61,$A7,Raw_Training!$C$2:$C$61,$C7,Raw_Training!$E$2:$E$61,1),"") -> 354.95657
A8: he_partial_zkp | B8: Partial HE + Norm-Bound ZKP Guard | C8: unthrottled | D8: 1 | E8: 79688 | F8: 37 | G8: 31332 | H8: 26566 | I8: =IFERROR(AVERAGEIFS(Raw_Training!$J$2:$J$61,Raw_Training!$A$2:$A$61,$A8,Raw_Training!$C$2:$C$61,$C8,Raw_Training!$E$2:$E$61,0),"") -> 154.94457 | J8: =IFERROR(AVERAGEIFS(Raw_Training!$J$2:$J$61,Raw_Training!$A$2:$A$61,$A8,Raw_Training!$C$2:$C$61,$C8,Raw_Training!$E$2:$E$61,1),"") -> 119.16623 | K8: =IFERROR(AVERAGEIFS(Raw_Training!$I$2:$I$61,Raw_Training!$A$2:$A$61,$A8,Raw_Training!$C$2:$C$61,$C8),"") | L8: =IFERROR(AVERAGEIFS(Raw_Training!$K$2:$K$61,Raw_Training!$A$2:$A$61,$A8,Raw_Training!$C$2:$C$61,$C8),"") -> 0.053283333 | M8: =IFERROR(AVERAGEIFS(Raw_Training!$L$2:$L$61,Raw_Training!$A$2:$A$61,$A8,Raw_Training!$C$2:$C$61,$C8),"") -> 0.00555 | N8: =IFERROR(AVERAGEIFS(Raw_Training!$S$2:$S$61,Raw_Training!$A$2:$A$61,$A8,Raw_Training!$C$2:$C$61,$C8),"") -> 0.12343167 | O8: =IFERROR(AVERAGEIFS(Raw_Training!$T$2:$T$61,Raw_Training!$A$2:$A$61,$A8,Raw_Training!$C$2:$C$61,$C8),"") -> 0.083941667 | P8: =IFERROR(AVERAGEIFS(Raw_Training!$U$2:$U$61,Raw_Training!$A$2:$A$61,$A8,Raw_Training!$C$2:$C$61,$C8),"") -> 1997583.3 | Q8: =IFERROR(AVERAGEIFS(Raw_Communication!$F$2:$F$61,Raw_Communication!$A$2:$A$61,$A8,Raw_Communication!$C$2:$C$61,$C8),"") -> 0.073543333 | R8: =IFERROR(AVERAGEIFS(Raw_RAM!$E$2:$E$31,Raw_RAM!$A$2:$A$31,$A8,Raw_RAM!$C$2:$C$31,$C8,Raw_RAM!$D$2:$D$31,"Client 0"),"") -> 394.4 | S8: =IFERROR(AVERAGEIFS(Raw_RAM!$E$2:$E$31,Raw_RAM!$A$2:$A$31,$A8,Raw_RAM!$C$2:$C$31,$C8,Raw_RAM!$D$2:$D$31,"Client 1"),"") -> 393.5 | T8: =IFERROR(AVERAGEIFS(Raw_RAM!$E$2:$E$31,Raw_RAM!$A$2:$A$31,$A8,Raw_RAM!$C$2:$C$31,$C8,Raw_RAM!$D$2:$D$31,"Server (aggregation)"),"") -> 60.6 | U8: =IFERROR(AVERAGEIFS(Raw_Aggregation!$E$2:$E$31,Raw_Aggregation!$A$2:$A$31,$A8,Raw_Aggregation!$C$2:$C$31,$C8),"") -> 0.012593333 | V8: =IFERROR(AVERAGEIFS(Raw_Aggregation!$F$2:$F$31,Raw_Aggregation!$A$2:$A$31,$A8,Raw_Aggregation!$C$2:$C$31,$C8),"") -> 0.0016933333 | W8: =IFERROR(AVERAGEIFS(Raw_Aggregation!$G$2:$G$31,Raw_Aggregation!$A$2:$A$31,$A8,Raw_Aggregation!$C$2:$C$31,$C8),"") -> 0.0011933333 | X8: =IFERROR(AVERAGEIFS(Raw_Aggregation!$H$2:$H$31,Raw_Aggregation!$A$2:$A$31,$A8,Raw_Aggregation!$C$2:$C$31,$C8),"") -> 0.01111 | Y8: =IFERROR(AVERAGEIFS(Raw_Aggregation!$I$2:$I$31,Raw_Aggregation!$A$2:$A$31,$A8,Raw_Aggregation!$C$2:$C$31,$C8),"") | Z8: =IFERROR(AVERAGEIFS(Raw_Training!$W$2:$W$61,Raw_Training!$A$2:$A$61,$A8,Raw_Training!$C$2:$C$61,$C8,Raw_Training!$E$2:$E$61,0),"") -> 156.20517 | AA8: =IFERROR(AVERAGEIFS(Raw_Training!$W$2:$W$61,Raw_Training!$A$2:$A$61,$A8,Raw_Training!$C$2:$C$61,$C8,Raw_Training!$E$2:$E$61,1),"") -> 120.46677
A9: he_partial_zkp | B9: Partial HE + Norm-Bound ZKP Guard | C9: throttled | D9: 0.5 | E9: 79688 | F9: 37 | G9: 31332 | H9: 26566 | I9: =IFERROR(AVERAGEIFS(Raw_Training!$J$2:$J$61,Raw_Training!$A$2:$A$61,$A9,Raw_Training!$C$2:$C$61,$C9,Raw_Training!$E$2:$E$61,0),"") -> 276.2496 | J9: =IFERROR(AVERAGEIFS(Raw_Training!$J$2:$J$61,Raw_Training!$A$2:$A$61,$A9,Raw_Training!$C$2:$C$61,$C9,Raw_Training!$E$2:$E$61,1),"") -> 226.6175 | K9: =IFERROR(AVERAGEIFS(Raw_Training!$I$2:$I$61,Raw_Training!$A$2:$A$61,$A9,Raw_Training!$C$2:$C$61,$C9),"") | L9: =IFERROR(AVERAGEIFS(Raw_Training!$K$2:$K$61,Raw_Training!$A$2:$A$61,$A9,Raw_Training!$C$2:$C$61,$C9),"") -> 0.087433333 | M9: =IFERROR(AVERAGEIFS(Raw_Training!$L$2:$L$61,Raw_Training!$A$2:$A$61,$A9,Raw_Training!$C$2:$C$61,$C9),"") -> 0.0031833333 | N9: =IFERROR(AVERAGEIFS(Raw_Training!$S$2:$S$61,Raw_Training!$A$2:$A$61,$A9,Raw_Training!$C$2:$C$61,$C9),"") -> 0.18882333 | O9: =IFERROR(AVERAGEIFS(Raw_Training!$T$2:$T$61,Raw_Training!$A$2:$A$61,$A9,Raw_Training!$C$2:$C$61,$C9),"") -> 0.13160167 | P9: =IFERROR(AVERAGEIFS(Raw_Training!$U$2:$U$61,Raw_Training!$A$2:$A$61,$A9,Raw_Training!$C$2:$C$61,$C9),"") -> 1997261.2 | Q9: =IFERROR(AVERAGEIFS(Raw_Communication!$F$2:$F$61,Raw_Communication!$A$2:$A$61,$A9,Raw_Communication!$C$2:$C$61,$C9),"") -> 0.11989333 | R9: =IFERROR(AVERAGEIFS(Raw_RAM!$E$2:$E$31,Raw_RAM!$A$2:$A$31,$A9,Raw_RAM!$C$2:$C$31,$C9,Raw_RAM!$D$2:$D$31,"Client 0"),"") -> 397.3 | S9: =IFERROR(AVERAGEIFS(Raw_RAM!$E$2:$E$31,Raw_RAM!$A$2:$A$31,$A9,Raw_RAM!$C$2:$C$31,$C9,Raw_RAM!$D$2:$D$31,"Client 1"),"") -> 392.6 | T9: =IFERROR(AVERAGEIFS(Raw_RAM!$E$2:$E$31,Raw_RAM!$A$2:$A$31,$A9,Raw_RAM!$C$2:$C$31,$C9,Raw_RAM!$D$2:$D$31,"Server (aggregation)"),"") -> 60 | U9: =IFERROR(AVERAGEIFS(Raw_Aggregation!$E$2:$E$31,Raw_Aggregation!$A$2:$A$31,$A9,Raw_Aggregation!$C$2:$C$31,$C9),"") -> 0.01459 | V9: =IFERROR(AVERAGEIFS(Raw_Aggregation!$F$2:$F$31,Raw_Aggregation!$A$2:$A$31,$A9,Raw_Aggregation!$C$2:$C$31,$C9),"") -> 0.0021233333 | W9: =IFERROR(AVERAGEIFS(Raw_Aggregation!$G$2:$G$31,Raw_Aggregation!$A$2:$A$31,$A9,Raw_Aggregation!$C$2:$C$31,$C9),"") -> 0.0015533333 | X9: =IFERROR(AVERAGEIFS(Raw_Aggregation!$H$2:$H$31,Raw_Aggregation!$A$2:$A$31,$A9,Raw_Aggregation!$C$2:$C$31,$C9),"") -> 0.025256667 | Y9: =IFERROR(AVERAGEIFS(Raw_Aggregation!$I$2:$I$31,Raw_Aggregation!$A$2:$A$31,$A9,Raw_Aggregation!$C$2:$C$31,$C9),"") | Z9: =IFERROR(AVERAGEIFS(Raw_Training!$W$2:$W$61,Raw_Training!$A$2:$A$61,$A9,Raw_Training!$C$2:$C$61,$C9,Raw_Training!$E$2:$E$61,0),"") -> 277.8051 | AA9: =IFERROR(AVERAGEIFS(Raw_Training!$W$2:$W$61,Raw_Training!$A$2:$A$61,$A9,Raw_Training!$C$2:$C$61,$C9,Raw_Training!$E$2:$E$61,1),"") -> 228.28673
A10: dp | B10: DP-SGD (Opacus, eps=3.0) | C10: unthrottled | D10: 1 | E10: 79688 | F10: 37 | G10: 31332 | H10: 26566 | I10: =IFERROR(AVERAGEIFS(Raw_Training!$J$2:$J$61,Raw_Training!$A$2:$A$61,$A10,Raw_Training!$C$2:$C$61,$C10,Raw_Training!$E$2:$E$61,0),"") -> 688.69003 | J10: =IFERROR(AVERAGEIFS(Raw_Training!$J$2:$J$61,Raw_Training!$A$2:$A$61,$A10,Raw_Training!$C$2:$C$61,$C10,Raw_Training!$E$2:$E$61,1),"") -> 676.3904 | K10: =IFERROR(AVERAGEIFS(Raw_Training!$I$2:$I$61,Raw_Training!$A$2:$A$61,$A10,Raw_Training!$C$2:$C$61,$C10),"") -> 1.1968333 | L10: =IFERROR(AVERAGEIFS(Raw_Training!$K$2:$K$61,Raw_Training!$A$2:$A$61,$A10,Raw_Training!$C$2:$C$61,$C10),"") | M10: =IFERROR(AVERAGEIFS(Raw_Training!$L$2:$L$61,Raw_Training!$A$2:$A$61,$A10,Raw_Training!$C$2:$C$61,$C10),"") | N10: =IFERROR(AVERAGEIFS(Raw_Training!$S$2:$S$61,Raw_Training!$A$2:$A$61,$A10,Raw_Training!$C$2:$C$61,$C10),"") -> 0.20079833 | O10: =IFERROR(AVERAGEIFS(Raw_Training!$T$2:$T$61,Raw_Training!$A$2:$A$61,$A10,Raw_Training!$C$2:$C$61,$C10),"") -> 0.13267167 | P10: =IFERROR(AVERAGEIFS(Raw_Training!$U$2:$U$61,Raw_Training!$A$2:$A$61,$A10,Raw_Training!$C$2:$C$61,$C10),"") -> 2828816 | Q10: =IFERROR(AVERAGEIFS(Raw_Communication!$F$2:$F$61,Raw_Communication!$A$2:$A$61,$A10,Raw_Communication!$C$2:$C$61,$C10),"") -> 0.12000167 | R10: =IFERROR(AVERAGEIFS(Raw_RAM!$E$2:$E$31,Raw_RAM!$A$2:$A$31,$A10,Raw_RAM!$C$2:$C$31,$C10,Raw_RAM!$D$2:$D$31,"Client 0"),"") -> 799.4 | S10: =IFERROR(AVERAGEIFS(Raw_RAM!$E$2:$E$31,Raw_RAM!$A$2:$A$31,$A10,Raw_RAM!$C$2:$C$31,$C10,Raw_RAM!$D$2:$D$31,"Client 1"),"") -> 784.1 | T10: =IFERROR(AVERAGEIFS(Raw_RAM!$E$2:$E$31,Raw_RAM!$A$2:$A$31,$A10,Raw_RAM!$C$2:$C$31,$C10,Raw_RAM!$D$2:$D$31,"Server (aggregation)"),"") -> 76.7 | U10: =IFERROR(AVERAGEIFS(Raw_Aggregation!$E$2:$E$31,Raw_Aggregation!$A$2:$A$31,$A10,Raw_Aggregation!$C$2:$C$31,$C10),"") | V10: =IFERROR(AVERAGEIFS(Raw_Aggregation!$F$2:$F$31,Raw_Aggregation!$A$2:$A$31,$A10,Raw_Aggregation!$C$2:$C$31,$C10),"") | W10: =IFERROR(AVERAGEIFS(Raw_Aggregation!$G$2:$G$31,Raw_Aggregation!$A$2:$A$31,$A10,Raw_Aggregation!$C$2:$C$31,$C10),"") | X10: =IFERROR(AVERAGEIFS(Raw_Aggregation!$H$2:$H$31,Raw_Aggregation!$A$2:$A$31,$A10,Raw_Aggregation!$C$2:$C$31,$C10),"") | Y10: =IFERROR(AVERAGEIFS(Raw_Aggregation!$I$2:$I$31,Raw_Aggregation!$A$2:$A$31,$A10,Raw_Aggregation!$C$2:$C$31,$C10),"") -> 0.03418 | Z10: =IFERROR(AVERAGEIFS(Raw_Training!$W$2:$W$61,Raw_Training!$A$2:$A$61,$A10,Raw_Training!$C$2:$C$61,$C10,Raw_Training!$E$2:$E$61,0),"") -> 691.86053 | AA10: =IFERROR(AVERAGEIFS(Raw_Training!$W$2:$W$61,Raw_Training!$A$2:$A$61,$A10,Raw_Training!$C$2:$C$61,$C10,Raw_Training!$E$2:$E$61,1),"") -> 679.96143
A11: dp | B11: DP-SGD (Opacus, eps=3.0) | C11: throttled | D11: 0.5 | E11: 79688 | F11: 37 | G11: 31332 | H11: 26566 | I11: =IFERROR(AVERAGEIFS(Raw_Training!$J$2:$J$61,Raw_Training!$A$2:$A$61,$A11,Raw_Training!$C$2:$C$61,$C11,Raw_Training!$E$2:$E$61,0),"") -> 2630.0957 | J11: =IFERROR(AVERAGEIFS(Raw_Training!$J$2:$J$61,Raw_Training!$A$2:$A$61,$A11,Raw_Training!$C$2:$C$61,$C11,Raw_Training!$E$2:$E$61,1),"") -> 2128.2966 | K11: =IFERROR(AVERAGEIFS(Raw_Training!$I$2:$I$61,Raw_Training!$A$2:$A$61,$A11,Raw_Training!$C$2:$C$61,$C11),"") -> 2.5019667 | L11: =IFERROR(AVERAGEIFS(Raw_Training!$K$2:$K$61,Raw_Training!$A$2:$A$61,$A11,Raw_Training!$C$2:$C$61,$C11),"") | M11: =IFERROR(AVERAGEIFS(Raw_Training!$L$2:$L$61,Raw_Training!$A$2:$A$61,$A11,Raw_Training!$C$2:$C$61,$C11),"") | N11: =IFERROR(AVERAGEIFS(Raw_Training!$S$2:$S$61,Raw_Training!$A$2:$A$61,$A11,Raw_Training!$C$2:$C$61,$C11),"") -> 0.39408833 | O11: =IFERROR(AVERAGEIFS(Raw_Training!$T$2:$T$61,Raw_Training!$A$2:$A$61,$A11,Raw_Training!$C$2:$C$61,$C11),"") -> 0.49773333 | P11: =IFERROR(AVERAGEIFS(Raw_Training!$U$2:$U$61,Raw_Training!$A$2:$A$61,$A11,Raw_Training!$C$2:$C$61,$C11),"") -> 2828776 | Q11: =IFERROR(AVERAGEIFS(Raw_Communication!$F$2:$F$61,Raw_Communication!$A$2:$A$61,$A11,Raw_Communication!$C$2:$C$61,$C11),"") -> 0.34217667 | R11: =IFERROR(AVERAGEIFS(Raw_RAM!$E$2:$E$31,Raw_RAM!$A$2:$A$31,$A11,Raw_RAM!$C$2:$C$31,$C11,Raw_RAM!$D$2:$D$31,"Client 0"),"") -> 798.8 | S11: =IFERROR(AVERAGEIFS(Raw_RAM!$E$2:$E$31,Raw_RAM!$A$2:$A$31,$A11,Raw_RAM!$C$2:$C$31,$C11,Raw_RAM!$D$2:$D$31,"Client 1"),"") -> 792.6 | T11: =IFERROR(AVERAGEIFS(Raw_RAM!$E$2:$E$31,Raw_RAM!$A$2:$A$31,$A11,Raw_RAM!$C$2:$C$31,$C11,Raw_RAM!$D$2:$D$31,"Server (aggregation)"),"") -> 76.7 | U11: =IFERROR(AVERAGEIFS(Raw_Aggregation!$E$2:$E$31,Raw_Aggregation!$A$2:$A$31,$A11,Raw_Aggregation!$C$2:$C$31,$C11),"") | V11: =IFERROR(AVERAGEIFS(Raw_Aggregation!$F$2:$F$31,Raw_Aggregation!$A$2:$A$31,$A11,Raw_Aggregation!$C$2:$C$31,$C11),"") | W11: =IFERROR(AVERAGEIFS(Raw_Aggregation!$G$2:$G$31,Raw_Aggregation!$A$2:$A$31,$A11,Raw_Aggregation!$C$2:$C$31,$C11),"") | X11: =IFERROR(AVERAGEIFS(Raw_Aggregation!$H$2:$H$31,Raw_Aggregation!$A$2:$A$31,$A11,Raw_Aggregation!$C$2:$C$31,$C11),"") | Y11: =IFERROR(AVERAGEIFS(Raw_Aggregation!$I$2:$I$31,Raw_Aggregation!$A$2:$A$31,$A11,Raw_Aggregation!$C$2:$C$31,$C11),"") -> 0.088093333 | Z11: =IFERROR(AVERAGEIFS(Raw_Training!$W$2:$W$61,Raw_Training!$A$2:$A$61,$A11,Raw_Training!$C$2:$C$61,$C11,Raw_Training!$E$2:$E$61,0),"") -> 2636.6541 | AA11: =IFERROR(AVERAGEIFS(Raw_Training!$W$2:$W$61,Raw_Training!$A$2:$A$61,$A11,Raw_Training!$C$2:$C$61,$C11,Raw_Training!$E$2:$E$61,1),"") -> 2134.9483

Sheet Raw_Training
A1: Mode | B1: Mode (label) | C1: CPU Profile | D1: vCPU | E1: Client ID | F1: Train Rows | G1: Test Rows | H1: Round | I1: DP Setup Time (s) | J1: Train Time (s) | K1: HE Encrypt Time (s) | L1: ZKP Proof Time (s) | M1: ZKP Claimed Norm* | N1: N Chunks | O1: Pct Encrypted (%) | P1: DP Epsilon Target | Q1: DP Epsilon Achieved | R1: DP Noise Multiplier | S1: Serialize Time (s) | T1: Communication Send Time (s) | U1: Payload Bytes | V1: Communication OK | W1: Round Wall Time (s)
A2: baseline | B2: Baseline (no defense) | C2: unthrottled | D2: 1 | E2: 0 | F2: 31332 | G2: 7834 | H2: 1 | J2: 126.9766 | S2: 0.12079 | T2: 0.09108 | U2: 1756605 | V2: =TRUE() -> TRUE | W2: 128.0944
A3: baseline | B3: Baseline (no defense) | C3: unthrottled | D3: 1 | E3: 0 | F3: 31332 | G3: 7834 | H3: 2 | J3: 135.4661 | S3: 0.12106 | T3: 0.08145 | U3: 1755544 | V3: =TRUE() -> TRUE | W3: 136.6903
A4: baseline | B4: Baseline (no defense) | C4: unthrottled | D4: 1 | E4: 0 | F4: 31332 | G4: 7834 | H4: 3 | J4: 141.4477 | S4: 0.12051 | T4: 0.08139 | U4: 1754576 | V4: =TRUE() -> TRUE | W4: 142.6148
A5: baseline | B5: Baseline (no defense) | C5: unthrottled | D5: 1 | E5: 1 | F5: 26566 | G5: 6642 | H5: 1 | J5: 105.9923 | S5: 0.12453 | T5: 0.09896 | U5: 1756663 | V5: =TRUE() -> TRUE | W5: 107.2019
A6: baseline | B6: Baseline (no defense) | C6: unthrottled | D6: 1 | E6: 1 | F6: 26566 | G6: 6642 | H6: 2 | J6: 101.966 | S6: 0.13023 | T6: 0.07714 | U6: 1755840 | V6: =TRUE() -> TRUE | W6: 103.3142
A7: baseline | B7: Baseline (no defense) | C7: unthrottled | D7: 1 | E7: 1 | F7: 26566 | G7: 6642 | H7: 3 | J7: 100.6436 | S7: 0.11916 | T7: 0.07491 | U7: 1755113 | V7: =TRUE() -> TRUE | W7: 102.2179
A8: baseline | B8: Baseline (no defense) | C8: throttled | D8: 0.5 | E8: 0 | F8: 31332 | G8: 7834 | H8: 1 | J8: 399.1857 | S8: 0.22769 | T8: 0.11026 | U8: 1756649 | V8: =TRUE() -> TRUE | W8: 400.7938
A9: baseline | B9: Baseline (no defense) | C9: throttled | D9: 0.5 | E9: 0 | F9: 31332 | G9: 7834 | H9: 2 | J9: 448.2425 | S9: 0.27065 | T9: 0.36789 | U9: 1755566 | V9: =TRUE() -> TRUE | W9: 450.0351
A10: baseline | B10: Baseline (no defense) | C10: throttled | D10: 0.5 | E10: 0 | F10: 31332 | G10: 7834 | H10: 3 | J10: 451.3578 | S10: 0.1957 | T10: 0.07959 | U10: 1754799 | V10: =TRUE() -> TRUE | W10: 452.6623
A11: baseline | B11: Baseline (no defense) | C11: throttled | D11: 0.5 | E11: 1 | F11: 26566 | G11: 6642 | H11: 1 | J11: 458.6799 | S11: 0.24105 | T11: 0.23357 | U11: 1756879 | V11: =TRUE() -> TRUE | W11: 460.2347
A12: baseline | B12: Baseline (no defense) | C12: throttled | D12: 0.5 | E12: 1 | F12: 26566 | G12: 6642 | H12: 2 | J12: 512.1855 | S12: 0.17515 | T12: 0.12731 | U12: 1755833 | V12: =TRUE() -> TRUE | W12: 513.4538
A13: baseline | B13: Baseline (no defense) | C13: throttled | D13: 0.5 | E13: 1 | F13: 26566 | G13: 6642 | H13: 3 | J13: 521.9777 | S13: 0.19576 | T13: 0.12575 | U13: 1754936 | V13: =TRUE() -> TRUE | W13: 524.0408
A14: he_full | B14: Full-Model HE (CKKS) | C14: unthrottled | D14: 1 | E14: 0 | F14: 31332 | G14: 7834 | H14: 1 | J14: 133.2797 | K14: 0.294 | N14: 40 | O14: 100 | S14: 0.03036 | T14: 0.06065 | U14: 4562330 | V14: =TRUE() -> TRUE | W14: 134.05
A15: he_full | B15: Full-Model HE (CKKS) | C15: unthrottled | D15: 1 | E15: 0 | F15: 31332 | G15: 7834 | H15: 2 | J15: 132.3062 | K15: 0.4178 | N15: 40 | O15: 100 | S15: 0.03181 | T15: 0.03575 | U15: 4563330 | V15: =TRUE() -> TRUE | W15: 132.9805
A16: he_full | B16: Full-Model HE (CKKS) | C16: unthrottled | D16: 1 | E16: 0 | F16: 31332 | G16: 7834 | H16: 3 | J16: 139.3151 | K16: 0.2918 | N16: 40 | O16: 100 | S16: 0.02715 | T16: 0.03917 | U16: 4562874 | V16: =TRUE() -> TRUE | W16: 140.0311
A17: he_full | B17: Full-Model HE (CKKS) | C17: unthrottled | D17: 1 | E17: 1 | F17: 26566 | G17: 6642 | H17: 1 | J17: 73.8445 | K17: 0.2791 | N17: 40 | O17: 100 | S17: 0.0306 | T17: 0.05504 | U17: 4563210 | V17: =TRUE() -> TRUE | W17: 74.5978
A18: he_full | B18: Full-Model HE (CKKS) | C18: unthrottled | D18: 1 | E18: 1 | F18: 26566 | G18: 6642 | H18: 2 | J18: 86.332 | K18: 0.3676 | N18: 40 | O18: 100 | S18: 0.04067 | T18: 0.03896 | U18: 4562842 | V18: =TRUE() -> TRUE | W18: 87.0644
A19: he_full | B19: Full-Model HE (CKKS) | C19: unthrottled | D19: 1 | E19: 1 | F19: 26566 | G19: 6642 | H19: 3 | J19: 86.5603 | K19: 0.3664 | N19: 40 | O19: 100 | S19: 0.02763 | T19: 0.03407 | U19: 4562738 | V19: =TRUE() -> TRUE | W19: 87.2364
A20: he_full | B20: Full-Model HE (CKKS) | C20: throttled | D20: 0.5 | E20: 0 | F20: 31332 | G20: 7834 | H20: 1 | J20: 629.0293 | K20: 0.6028 | N20: 40 | O20: 100 | S20: 0.02297 | T20: 0.04823 | U20: 4563010 | V20: =TRUE() -> TRUE | W20: 630.3041
A21: he_full | B21: Full-Model HE (CKKS) | C21: throttled | D21: 0.5 | E21: 0 | F21: 31332 | G21: 7834 | H21: 2 | J21: 634.3335 | K21: 0.6311 | N21: 40 | O21: 100 | S21: 0.05974 | T21: 0.183 | U21: 4564778 | V21: =TRUE() -> TRUE | W21: 635.715
A22: he_full | B22: Full-Model HE (CKKS) | C22: throttled | D22: 0.5 | E22: 0 | F22: 31332 | G22: 7834 | H22: 3 | J22: 627.6369 | K22: 0.5384 | N22: 40 | O22: 100 | S22: 0.02715 | T22: 0.04976 | U22: 4562958 | V22: =TRUE() -> TRUE | W22: 628.879
A23: he_full | B23: Full-Model HE (CKKS) | C23: throttled | D23: 0.5 | E23: 1 | F23: 26566 | G23: 6642 | H23: 1 | J23: 204.1705 | K23: 0.5844 | N23: 40 | O23: 100 | S23: 0.04314 | T23: 0.04186 | U23: 4562642 | V23: =TRUE() -> TRUE | W23: 205.4116
A24: he_full | B24: Full-Model HE (CKKS) | C24: throttled | D24: 0.5 | E24: 1 | F24: 26566 | G24: 6642 | H24: 2 | J24: 183.9433 | K24: 0.6003 | N24: 40 | O24: 100 | S24: 0.02278 | T24: 0.03614 | U24: 4563074 | V24: =TRUE() -> TRUE | W24: 185.1751
A25: he_full | B25: Full-Model HE (CKKS) | C25: throttled | D25: 0.5 | E25: 1 | F25: 26566 | G25: 6642 | H25: 3 | J25: 193.3411 | K25: 0.6072 | N25: 40 | O25: 100 | S25: 0.02762 | T25: 0.13439 | U25: 4563214 | V25: =TRUE() -> TRUE | W25: 194.5973
... A37: he_partial | B37: Partial HE (classifier head only) | C37: throttled | D37: 0.5 | E37: 1 | F37: 26566 | G37: 6642 | H37: 3 | J37: 357.1464 | K37: 0.0286 | N37: 3 | O37: 5.8445938 | S37: 0.18992 | T37: 0.08071 | U37: 1997290 | V37: =TRUE() -> TRUE | W37: 358.6517
A38: he_partial_zkp | B38: Partial HE + Norm-Bound ZKP Guard | C38: unthrottled | D38: 1 | E38: 0 | F38: 31332 | G38: 7834 | H38: 1 | J38: 157.1768 | K38: 0.0347 | L38: 0.0061 | M38: 0 | N38: 3 | O38: 5.8445938 | S38: 0.12404 | T38: 0.08572 | U38: 1998246 | V38: =TRUE() -> TRUE | W38: 158.5163
A39: he_partial_zkp | B39: Partial HE + Norm-Bound ZKP Guard | C39: unthrottled | D39: 1 | E39: 0 | F39: 31332 | G39: 7834 | H39: 2 | J39: 150.4446 | K39: 0.0313 | L39: 0.0017 | M39: 0 | N39: 3 | O39: 5.8445938 | S39: 0.12521 | T39: 0.07304 | U39: 1997792 | V39: =TRUE() -> TRUE | W39: 151.7096
A40: he_partial_zkp | B40: Partial HE + Norm-Bound ZKP Guard | C40: unthrottled | D40: 1 | E40: 0 | F40: 31332 | G40: 7834 | H40: 3 | J40: 157.2123 | K40: 0.1091 | L40: 0.0015 | M40: 0 | N40: 3 | O40: 5.8445938 | S40: 0.11366 | T40: 0.07644 | U40: 1997011 | V40: =TRUE() -> TRUE | W40: 158.3896
A41: he_partial_zkp | B41: Partial HE + Norm-Bound ZKP Guard | C41: unthrottled | D41: 1 | E41: 1 | F41: 26566 | G41: 6642 | H41: 1 | J41: 109.5917 | K41: 0.0217 | L41: 0.0219 | M41: 0 | N41: 3 | O41: 5.8445938 | S41: 0.11803 | T41: 0.11078 | U41: 1998254 | V41: =TRUE() -> TRUE | W41: 110.9437
A42: he_partial_zkp | B42: Partial HE + Norm-Bound ZKP Guard | C42: unthrottled | D42: 1 | E42: 1 | F42: 26566 | G42: 6642 | H42: 2 | J42: 122.73 | K42: 0.0999 | L42: 0.0011 | M42: 0 | N42: 3 | O42: 5.8445938 | S42: 0.13639 | T42: 0.08049 | U42: 1997709 | V42: =TRUE() -> TRUE | W42: 124.0385
A43: he_partial_zkp | B43: Partial HE + Norm-Bound ZKP Guard | C43: unthrottled | D43: 1 | E43: 1 | F43: 26566 | G43: 6642 | H43: 3 | J43: 125.177 | K43: 0.023 | L43: 0.001 | M43: 0 | N43: 3 | O43: 5.8445938 | S43: 0.12326 | T43: 0.07718 | U43: 1996488 | V43: =TRUE() -> TRUE | W43: 126.4181
A44: he_partial_zkp | B44: Partial HE + Norm-Bound ZKP Guard | C44: throttled | D44: 0.5 | E44: 0 | F44: 31332 | G44: 7834 | H44: 1 | J44: 292.7581 | K44: 0.0728 | L44: 0.0065 | M44: 0 | N44: 3 | O44: 5.8445938 | S44: 0.18907 | T44: 0.18541 | U44: 1998079 | V44: =TRUE() -> TRUE | W44: 294.3798
A45: he_partial_zkp | B45: Partial HE + Norm-Bound ZKP Guard | C45: throttled | D45: 0.5 | E45: 0 | F45: 31332 | G45: 7834 | H45: 2 | J45: 261.1524 | K45: 0.1168 | L45: 0.001 | M45: 0 | N45: 3 | O45: 5.8445938 | S45: 0.18132 | T45: 0.09536 | U45: 1996729 | V45: =TRUE() -> TRUE | W45: 262.6857
A46: he_partial_zkp | B46: Partial HE + Norm-Bound ZKP Guard | C46: throttled | D46: 0.5 | E46: 0 | F46: 31332 | G46: 7834 | H46: 3 | J46: 274.8383 | K46: 0.1018 | L46: 0.0012 | M46: 0 | N46: 3 | O46: 5.8445938 | S46: 0.18392 | T46: 0.08807 | U46: 1996494 | V46: =TRUE() -> TRUE | W46: 276.3498
A47: he_partial_zkp | B47: Partial HE + Norm-Bound ZKP Guard | C47: throttled | D47: 0.5 | E47: 1 | F47: 26566 | G47: 6642 | H47: 1 | J47: 209.9805 | K47: 0.0225 | L47: 0.0074 | M47: 0 | N47: 3 | O47: 5.8445938 | S47: 0.22437 | T47: 0.12604 | U47: 1998239 | V47: =TRUE() -> TRUE | W47: 211.7253
A48: he_partial_zkp | B48: Partial HE + Norm-Bound ZKP Guard | C48: throttled | D48: 0.5 | E48: 1 | F48: 26566 | G48: 6642 | H48: 2 | J48: 236.2241 | K48: 0.1011 | L48: 0.002 | M48: 0 | N48: 3 | O48: 5.8445938 | S48: 0.18559 | T48: 0.18826 | U48: 1997622 | V48: =TRUE() -> TRUE | W48: 237.9462
A49: he_partial_zkp | B49: Partial HE + Norm-Bound ZKP Guard | C49: throttled | D49: 0.5 | E49: 1 | F49: 26566 | G49: 6642 | H49: 3 | J49: 233.6479 | K49: 0.1096 | L49: 0.001 | M49: 0 | N49: 3 | O49: 5.8445938 | S49: 0.16867 | T49: 0.10647 | U49: 1996404 | V49: =TRUE() -> TRUE | W49: 235.1887
A50: dp | B50: DP-SGD (Opacus, eps=3.0) | C50: unthrottled | D50: 1 | E50: 0 | F50: 31332 | G50: 7834 | H50: 1 | I50: 0.9665 | J50: 702.0823 | P50: 3 | Q50: 2.996223 | R50: 0.79833984 | S50: 0.24035 | T50: 0.17228 | U50: 2829057 | V50: =TRUE() -> TRUE | W50: 706.0779
A51: dp | B51: DP-SGD (Opacus, eps=3.0) | C51: unthrottled | D51: 1 | E51: 0 | F51: 31332 | G51: 7834 | H51: 2 | I51: 1.1334 | J51: 683.5806 | P51: 3 | Q51: 2.996223 | R51: 0.79833984 | S51: 0.18869 | T51: 0.11832 | U51: 2828080 | V51: =TRUE() -> TRUE | W51: 686.3514
...

Sheet Raw_Communication
A1: Mode | B1: Mode (label) | C1: CPU Profile | D1: Client ID | E1: Round | F1: Daemon Recv Time (s) | G1: Payload Bytes | H1: Wall Time Since Daemon Start (s)
A2: baseline | B2: Baseline (no defense) | C2: unthrottled | D2: 0 | E2: 1 | F2: 0.07056 | G2: 1756605 | H2: 138.652
A3: baseline | B3: Baseline (no defense) | C3: unthrottled | D3: 1 | E3: 1 | F3: 0.07906 | G3: 1756663 | H3: 117.787
A4: baseline | B4: Baseline (no defense) | C4: unthrottled | D4: 0 | E4: 2 | F4: 0.07015 | G4: 1755544 | H4: 275.34
A5: baseline | B5: Baseline (no defense) | C5: unthrottled | D5: 1 | E5: 2 | F5: 0.06785 | G5: 1755840 | H5: 221.1
A6: baseline | B6: Baseline (no defense) | C6: unthrottled | D6: 0 | E6: 3 | F6: 0.07122 | G6: 1754576 | H6: 417.956
A7: baseline | B7: Baseline (no defense) | C7: unthrottled | D7: 1 | E7: 3 | F7: 0.06734 | G7: 1755113 | H7: 323.321
A8: baseline | B8: Baseline (no defense) | C8: throttled | D8: 0 | E8: 1 | F8: 0.0929 | G8: 1756649 | H8: 412.398
A9: baseline | B9: Baseline (no defense) | C9: throttled | D9: 1 | E9: 1 | F9: 0.21647 | G9: 1756879 | H9: 471.876
A10: baseline | B10: Baseline (no defense) | C10: throttled | D10: 0 | E10: 2 | F10: 0.30616 | G10: 1755566 | H10: 862.432
A11: baseline | B11: Baseline (no defense) | C11: throttled | D11: 1 | E11: 2 | F11: 0.11925 | G11: 1755833 | H11: 985.33
A12: baseline | B12: Baseline (no defense) | C12: throttled | D12: 0 | E12: 3 | F12: 0.07214 | G12: 1754799 | H12: 1315.097
A13: baseline | B13: Baseline (no defense) | C13: throttled | D13: 1 | E13: 3 | F13: 0.11768 | G13: 1754936 | H13: 1509.371
... A61: dp | B61: DP-SGD (Opacus, eps=3.0) | C61: throttled | D61: 1 | E61: 3 | F61: 0.3826 | G61: 2827765 | H61: 6424.467

Sheet Raw_Aggregation
A1: Mode | B1: Mode (label) | C1: CPU Profile | D1: Round | E1: Aggregate Time (s) | F1: Decrypt Time (s) | G1: ZKP Verify Time (s) | H1: ZKP MAD Threshold Time (s) | I1: Adaptive Krum Time (s) | J1: N Clients (Synthetic) | K1: N Clients (Real) | L1: Num Kept | M1: Num Dropped
A2: baseline | B2: Baseline (no defense) | C2: unthrottled | D2: 1 | I2: 0.04352 | J2: 10 | K2: 2 | L2: 10 | M2: 0
A3: baseline | B3: Baseline (no defense) | C3: unthrottled | D3: 2 | I3: 0.01614 | J3: 10 | K3: 2 | L3: 10 | M3: 0
A4: baseline | B4: Baseline (no defense) | C4: unthrottled | D4: 3 | I4: 0.01095 | J4: 10 | K4: 2 | L4: 10 | M4: 0
A5: baseline | B5: Baseline (no defense) | C5: throttled | D5: 1 | I5: 0.10191 | J5: 10 | K5: 2 | L5: 10 | M5: 0
A6: baseline | B6: Baseline (no defense) | C6: throttled | D6: 2 | I6: 0.01883 | J6: 10 | K6: 2 | L6: 10 | M6: 0
A7: baseline | B7: Baseline (no defense) | C7: throttled | D7: 3 | I7: 0.06459 | J7: 10 | K7: 2 | L7: 10 | M7: 0
A8: he_full | B8: Full-Model HE (CKKS) | C8: unthrottled | D8: 1 | E8: 0.11704 | F8: 0.02986
A9: he_full | B9: Full-Model HE (CKKS) | C9: unthrottled | D9: 2 | E9: 0.11847 | F9: 0.02475
A10: he_full | B10: Full-Model HE (CKKS) | C10: unthrottled | D10: 3 | E10: 0.11473 | F10: 0.02753
A11: he_full | B11: Full-Model HE (CKKS) | C11: throttled | D11: 1 | E11: 0.28172 | F11: 0.0298
A12: he_full | B12: Full-Model HE (CKKS) | C12: throttled | D12: 2 | E12: 0.22805 | F12: 0.0778
A13: he_full | B13: Full-Model HE (CKKS) | C13: throttled | D13: 3 | E13: 0.25723 | F13: 0.02687
A14: he_partial | B14: Partial HE (classifier head only) | C14: unthrottled | D14: 1 | E14: 0.01251 | F14: 0.00168
A15: he_partial | B15: Partial HE (classifier head only) | C15: unthrottled | D15: 2 | E15: 0.01435 | F15: 0.00179
A16: he_partial | B16: Partial HE (classifier head only) | C16: unthrottled | D16: 3 | E16: 0.01082 | F16: 0.00164
A17: he_partial | B17: Partial HE (classifier head only) | C17: throttled | D17: 1 | E17: 0.07151 | F17: 0.0023
A18: he_partial | B18: Partial HE (classifier head only) | C18: throttled | D18: 2 | E18: 0.01662 | F18: 0.00194
A19: he_partial | B19: Partial HE (classifier head only) | C19: throttled | D19: 3 | E19: 0.01382 | F19: 0.00176
A20: he_partial_zkp | B20: Partial HE + Norm-Bound ZKP Guard | C20: unthrottled | D20: 1 | E20: 0.01337 | F20: 0.00177 | G20: 0.00114 | H20: 0.03281
A21: he_partial_zkp | B21: Partial HE + Norm-Bound ZKP Guard | C21: unthrottled | D21: 2 | E21: 0.01269 | F21: 0.00162 | G21: 0.00116 | H21: 0.00027
A22: he_partial_zkp | B22: Partial HE + Norm-Bound ZKP Guard | C22: unthrottled | D22: 3 | E22: 0.01172 | F22: 0.00169 | G22: 0.00128 | H22: 0.00025
A23: he_partial_zkp | B23: Partial HE + Norm-Bound ZKP Guard | C23: throttled | D23: 1 | E23: 0.01475 | F23: 0.0019 | G23: 0.00134 | H23: 0.07506
A24: he_partial_zkp | B24: Partial HE + Norm-Bound ZKP Guard | C24: throttled | D24: 2 | E24: 0.01613 | F24: 0.00236 | G24: 0.00149 | H24: 0.00035
A25: he_partial_zkp | B25: Partial HE + Norm-Bound ZKP Guard | C25: throttled | D25: 3 | E25: 0.01289 | F25: 0.00211 | G25: 0.00183 | H25: 0.00036
A26: dp | B26: DP-SGD (Opacus, eps=3.0) | C26: unthrottled | D26: 1 | I26: 0.06558 | J26: 10 | K26: 2 | L26: 10 | M26: 0
A27: dp | B27: DP-SGD (Opacus, eps=3.0) | C27: unthrottled | D27: 2 | I27: 0.02132 | J27: 10 | K27: 2 | L27: 10 | M27: 0
A28: dp | B28: DP-SGD (Opacus, eps=3.0) | C28: unthrottled | D28: 3 | I28: 0.01564 | J28: 10 | K28: 2 | L28: 10 | M28: 0
A29: dp | B29: DP-SGD (Opacus, eps=3.0) | C29: throttled | D29: 1 | I29: 0.2227 | J29: 10 | K29: 2 | L29: 10 | M29: 0
A30: dp | B30: DP-SGD (Opacus, eps=3.0) | C30: throttled | D30: 2 | I30: 0.02433 | J30: 10 | K30: 2 | L30: 10 | M30: 0
A31: dp | B31: DP-SGD (Opacus, eps=3.0) | C31: throttled | D31: 3 | I31: 0.01725 | J31: 10 | K31: 2 | L31: 9 | M31: 1

Sheet Raw_RAM
A1: Mode | B1: Mode (label) | C1: CPU Profile | D1: Process | E1: Peak RAM (MB) | F1: Avg RAM (MB) | G1: N RAM Samples | H1: Real cgroup Mem Limit (MB) | I1: Real cgroup CPU Limit (cores)
A2: baseline | B2: Baseline (no defense) | C2: unthrottled | D2: Client 0 | E2: 382.9 | F2: 366.9 | G2: 1571 | H2: 2048 | I2: 1
A3: baseline | B3: Baseline (no defense) | C3: unthrottled | D3: Client 1 | E3: 382.4 | F3: 375.4 | G3: 1199 | H3: 2048 | I3: 1
A4: baseline | B4: Baseline (no defense) | C4: unthrottled | D4: Server (aggregation) | E4: 63.3 | F4: 49.5
A5: baseline | B5: Baseline (no defense) | C5: throttled | D5: Client 0 | E5: 385.9 | F5: 373.3 | G5: 4904 | H5: 2048 | I5: 0.5
A6: baseline | B6: Baseline (no defense) | C6: throttled | D6: Client 1 | E6: 382.4 | F6: 367 | G6: 5590 | H6: 2048 | I6: 0.5
A7: baseline | B7: Baseline (no defense) | C7: throttled | D7: Server (aggregation) | E7: 63.1 | F7: 50.8
A8: he_full | B8: Full-Model HE (CKKS) | C8: unthrottled | D8: Client 0 | E8: 401.1 | F8: 379.3 | G8: 1571 | H8: 2048 | I8: 1
A9: he_full | B9: Full-Model HE (CKKS) | C9: unthrottled | D9: Client 1 | E9: 396.2 | F9: 376.3 | G9: 960 | H9: 2048 | I9: 1
A10: he_full | B10: Full-Model HE (CKKS) | C10: unthrottled | D10: Server (aggregation) | E10: 72.9 | F10: 56
A11: he_full | B11: Full-Model HE (CKKS) | C11: throttled | D11: Client 0 | E11: 399.5 | F11: 378.3 | G11: 7144 | H11: 2048 | I11: 0.5
A12: he_full | B12: Full-Model HE (CKKS) | C12: throttled | D12: Client 1 | E12: 399.5 | F12: 375.5 | G12: 2233 | H12: 2048 | I12: 0.5
A13: he_full | B13: Full-Model HE (CKKS) | C13: throttled | D13: Server (aggregation) | E13: 72.9 | F13: 56.9
A14: he_partial | B14: Partial HE (classifier head only) | C14: unthrottled | D14: Client 0 | E14: 394.7 | F14: 378.9 | G14: 1641 | H14: 2048 | I14: 1
A15: he_partial | B15: Partial HE (classifier head only) | C15: unthrottled | D15: Client 1 | E15: 392.8 | F15: 376.5 | G15: 1288 | H15: 2048 | I15: 1
A16: he_partial | B16: Partial HE (classifier head only) | C16: unthrottled | D16: Server (aggregation) | E16: 51.5 | F16: 44.8
A17: he_partial | B17: Partial HE (classifier head only) | C17: throttled | D17: Client 0 | E17: 395.2 | F17: 377 | G17: 6894 | H17: 2048 | I17: 0.5
A18: he_partial | B18: Partial HE (classifier head only) | C18: throttled | D18: Client 1 | E18: 392.6 | F18: 375.4 | G18: 3970 | H18: 2048 | I18: 0.5
A19: he_partial | B19: Partial HE (classifier head only) | C19: throttled | D19: Server (aggregation) | E19: 53.9 | F19: 44.1
A20: he_partial_zkp | B20: Partial HE + Norm-Bound ZKP Guard | C20: unthrottled | D20: Client 0 | E20: 394.4 | F20: 376.7 | G20: 1811 | H20: 2048 | I20: 1
A21: he_partial_zkp | B21: Partial HE + Norm-Bound ZKP Guard | C21: unthrottled | D21: Client 1 | E21: 393.5 | F21: 378 | G21: 1398 | H21: 2048 | I21: 1
A22: he_partial_zkp | B22: Partial HE + Norm-Bound ZKP Guard | C22: unthrottled | D22: Server (aggregation) | E22: 60.6 | F22: 50.1
A23: he_partial_zkp | B23: Partial HE + Norm-Bound ZKP Guard | C23: throttled | D23: Client 0 | E23: 397.3 | F23: 375.6 | G23: 3146 | H23: 2048 | I23: 0.5
A24: he_partial_zkp | B24: Partial HE + Norm-Bound ZKP Guard | C24: throttled | D24: Client 1 | E24: 392.6 | F24: 375.3 | G24: 2583 | H24: 2048 | I24: 0.5
A25: he_partial_zkp | B25: Partial HE + Norm-Bound ZKP Guard | C25: throttled | D25: Server (aggregation) | E25: 60 | F25: 49.9
A26: dp | B26: DP-SGD (Opacus, eps=3.0) | C26: unthrottled | D26: Client 0 | E26: 799.4 | F26: 673.2 | G26: 8110 | H26: 2048 | I26: 1
A27: dp | B27: DP-SGD (Opacus, eps=3.0) | C27: unthrottled | D27: Client 1 | E27: 784.1 | F27: 660.8 | G27: 7807 | H27: 2048 | I27: 1
A28: dp | B28: DP-SGD (Opacus, eps=3.0) | C28: unthrottled | D28: Server (aggregation) | E28: 76.7 | F28: 57.6
A29: dp | B29: DP-SGD (Opacus, eps=3.0) | C29: throttled | D29: Client 0 | E29: 798.8 | F29: 652.4 | G29: 29665 | H29: 2048 | I29: 0.5
A30: dp | B30: DP-SGD (Opacus, eps=3.0) | C30: throttled | D30: Client 1 | E30: 792.6 | F30: 652 | G30: 24083 | H30: 2048 | I30: 0.5
A31: dp | B31: DP-SGD (Opacus, eps=3.0) | C31: throttled | D31: Server (aggregation) | E31: 76.7 | F31: 58.3

Sheet Known_Issues
A1: Known Data-Quality Issues -- Read Before Citing
A3: 1. ZKP Claimed Norm is always 0.0 (Raw_Training column "ZKP Claimed Norm*", he_partial_zkp runs only)
A4: This is a real bug in the test harness, not a property of the defense mechanism. The head-norm
A5: delta is computed as (trained classifier-head params) minus (classifier-head params captured
A6: before training). The "before training" snapshot was taken via tensor.cpu().numpy(), which for an
A7: already-CPU tensor returns a VIEW sharing memory with the tensor, not a copy. When the optimizer
A8: later mutates that tensor in-place during training, the earlier "before" snapshot is silently
A9: overwritten too -- so by the time the delta is computed, both sides of the subtraction point at
A10: the same post-training memory, and the norm is trivially zero every round, for every client, in
A11: both resource profiles.
A13: IMPACT: This affects ONLY the "ZKP Claimed Norm" column's displayed value. It does NOT affect:
A14: - ZKP Proof Time (s) -- norm computation cost is the same regardless of the input value
... A42: under this ceiling in every run (see Raw_RAM), confirming headroom was never the limiting factor.
